[2023-10-14T21:31:19.362+0000] {taskinstance.py:1159} INFO - Dependencies all met for dep_context=non-requeueable deps ti=<TaskInstance: pronostico_tiempo_dag1.insertar_datos manual__2023-10-14T21:30:50.511179+00:00 [queued]>
[2023-10-14T21:31:19.386+0000] {taskinstance.py:1159} INFO - Dependencies all met for dep_context=requeueable deps ti=<TaskInstance: pronostico_tiempo_dag1.insertar_datos manual__2023-10-14T21:30:50.511179+00:00 [queued]>
[2023-10-14T21:31:19.389+0000] {taskinstance.py:1361} INFO - Starting attempt 1 of 2
[2023-10-14T21:31:19.484+0000] {taskinstance.py:1382} INFO - Executing <Task(PythonOperator): insertar_datos> on 2023-10-14 21:30:50.511179+00:00
[2023-10-14T21:31:19.500+0000] {standard_task_runner.py:57} INFO - Started process 932 to run task
[2023-10-14T21:31:19.525+0000] {standard_task_runner.py:84} INFO - Running: ['***', 'tasks', 'run', 'pronostico_tiempo_dag1', 'insertar_datos', 'manual__2023-10-14T21:30:50.511179+00:00', '--job-id', '22', '--raw', '--subdir', 'DAGS_FOLDER/tiempo1.py', '--cfg-path', '/tmp/tmp4h6jb_gi']
[2023-10-14T21:31:19.541+0000] {standard_task_runner.py:85} INFO - Job 22: Subtask insertar_datos
[2023-10-14T21:31:19.740+0000] {task_command.py:416} INFO - Running <TaskInstance: pronostico_tiempo_dag1.insertar_datos manual__2023-10-14T21:30:50.511179+00:00 [running]> on host f314a0c7455b
[2023-10-14T21:31:20.074+0000] {taskinstance.py:1662} INFO - Exporting env vars: AIRFLOW_CTX_DAG_OWNER='Gustavo Lavalle' AIRFLOW_CTX_DAG_ID='pronostico_tiempo_dag1' AIRFLOW_CTX_TASK_ID='insertar_datos' AIRFLOW_CTX_EXECUTION_DATE='2023-10-14T21:30:50.511179+00:00' AIRFLOW_CTX_TRY_NUMBER='1' AIRFLOW_CTX_DAG_RUN_ID='manual__2023-10-14T21:30:50.511179+00:00'
[2023-10-14T21:31:20.077+0000] {taskinstance.py:1937} ERROR - Task failed with exception
Traceback (most recent call last):
  File "/home/airflow/.local/lib/python3.8/site-packages/airflow/operators/python.py", line 192, in execute
    return_value = self.execute_callable()
  File "/home/airflow/.local/lib/python3.8/site-packages/airflow/operators/python.py", line 209, in execute_callable
    return self.python_callable(*self.op_args, **self.op_kwargs)
  File "/opt/airflow/dags/tiempo1.py", line 64, in insertar_datos
    ti.xcom_push(key="insertar_datos", value=ti.xcom_pull(task_ids=[f'obtener_pronostico_{ciudad_key}' for ciudad_key in ciudades_keys]))
NameError: name 'ciudades_keys' is not defined
[2023-10-14T21:31:20.113+0000] {taskinstance.py:1400} INFO - Marking task as UP_FOR_RETRY. dag_id=pronostico_tiempo_dag1, task_id=insertar_datos, execution_date=20231014T213050, start_date=20231014T213119, end_date=20231014T213120
[2023-10-14T21:31:20.192+0000] {standard_task_runner.py:104} ERROR - Failed to execute job 22 for task insertar_datos (name 'ciudades_keys' is not defined; 932)
[2023-10-14T21:31:20.236+0000] {local_task_job_runner.py:228} INFO - Task exited with return code 1
[2023-10-14T21:31:20.392+0000] {taskinstance.py:2778} INFO - 0 downstream tasks scheduled from follow-on schedule check
