[2023-10-14T21:42:33.384+0000] {taskinstance.py:1159} INFO - Dependencies all met for dep_context=non-requeueable deps ti=<TaskInstance: pronostico_tiempo_dag1.insertar_datos manual__2023-10-14T21:42:09.462441+00:00 [queued]>
[2023-10-14T21:42:33.402+0000] {taskinstance.py:1159} INFO - Dependencies all met for dep_context=requeueable deps ti=<TaskInstance: pronostico_tiempo_dag1.insertar_datos manual__2023-10-14T21:42:09.462441+00:00 [queued]>
[2023-10-14T21:42:33.403+0000] {taskinstance.py:1361} INFO - Starting attempt 1 of 2
[2023-10-14T21:42:33.451+0000] {taskinstance.py:1382} INFO - Executing <Task(PythonOperator): insertar_datos> on 2023-10-14 21:42:09.462441+00:00
[2023-10-14T21:42:33.461+0000] {standard_task_runner.py:57} INFO - Started process 1120 to run task
[2023-10-14T21:42:33.470+0000] {standard_task_runner.py:84} INFO - Running: ['***', 'tasks', 'run', 'pronostico_tiempo_dag1', 'insertar_datos', 'manual__2023-10-14T21:42:09.462441+00:00', '--job-id', '36', '--raw', '--subdir', 'DAGS_FOLDER/tiempo1.py', '--cfg-path', '/tmp/tmpp0r7ptpb']
[2023-10-14T21:42:33.476+0000] {standard_task_runner.py:85} INFO - Job 36: Subtask insertar_datos
[2023-10-14T21:42:33.574+0000] {task_command.py:416} INFO - Running <TaskInstance: pronostico_tiempo_dag1.insertar_datos manual__2023-10-14T21:42:09.462441+00:00 [running]> on host f314a0c7455b
[2023-10-14T21:42:33.752+0000] {taskinstance.py:1662} INFO - Exporting env vars: AIRFLOW_CTX_DAG_OWNER='Gustavo Lavalle' AIRFLOW_CTX_DAG_ID='pronostico_tiempo_dag1' AIRFLOW_CTX_TASK_ID='insertar_datos' AIRFLOW_CTX_EXECUTION_DATE='2023-10-14T21:42:09.462441+00:00' AIRFLOW_CTX_TRY_NUMBER='1' AIRFLOW_CTX_DAG_RUN_ID='manual__2023-10-14T21:42:09.462441+00:00'
[2023-10-14T21:42:33.784+0000] {taskinstance.py:1937} ERROR - Task failed with exception
Traceback (most recent call last):
  File "/home/airflow/.local/lib/python3.8/site-packages/airflow/operators/python.py", line 192, in execute
    return_value = self.execute_callable()
  File "/home/airflow/.local/lib/python3.8/site-packages/airflow/operators/python.py", line 209, in execute_callable
    return self.python_callable(*self.op_args, **self.op_kwargs)
  File "/opt/airflow/dags/tiempo1.py", line 76, in insertar_datos
    temperatura = pronostico['main']['temp']
TypeError: 'NoneType' object is not subscriptable
[2023-10-14T21:42:33.799+0000] {taskinstance.py:1400} INFO - Marking task as UP_FOR_RETRY. dag_id=pronostico_tiempo_dag1, task_id=insertar_datos, execution_date=20231014T214209, start_date=20231014T214233, end_date=20231014T214233
[2023-10-14T21:42:33.830+0000] {standard_task_runner.py:104} ERROR - Failed to execute job 36 for task insertar_datos ('NoneType' object is not subscriptable; 1120)
[2023-10-14T21:42:33.886+0000] {local_task_job_runner.py:228} INFO - Task exited with return code 1
[2023-10-14T21:42:33.935+0000] {taskinstance.py:2778} INFO - 0 downstream tasks scheduled from follow-on schedule check
