[2023-10-14T21:47:36.196+0000] {taskinstance.py:1159} INFO - Dependencies all met for dep_context=non-requeueable deps ti=<TaskInstance: pronostico_tiempo_dag1.insertar_datos manual__2023-10-14T21:42:09.462441+00:00 [queued]>
[2023-10-14T21:47:36.206+0000] {taskinstance.py:1159} INFO - Dependencies all met for dep_context=requeueable deps ti=<TaskInstance: pronostico_tiempo_dag1.insertar_datos manual__2023-10-14T21:42:09.462441+00:00 [queued]>
[2023-10-14T21:47:36.206+0000] {taskinstance.py:1361} INFO - Starting attempt 2 of 2
[2023-10-14T21:47:36.233+0000] {taskinstance.py:1382} INFO - Executing <Task(PythonOperator): insertar_datos> on 2023-10-14 21:42:09.462441+00:00
[2023-10-14T21:47:36.239+0000] {standard_task_runner.py:57} INFO - Started process 1185 to run task
[2023-10-14T21:47:36.244+0000] {standard_task_runner.py:84} INFO - Running: ['***', 'tasks', 'run', 'pronostico_tiempo_dag1', 'insertar_datos', 'manual__2023-10-14T21:42:09.462441+00:00', '--job-id', '37', '--raw', '--subdir', 'DAGS_FOLDER/tiempo1.py', '--cfg-path', '/tmp/tmp4es8f3f0']
[2023-10-14T21:47:36.248+0000] {standard_task_runner.py:85} INFO - Job 37: Subtask insertar_datos
[2023-10-14T21:47:36.303+0000] {task_command.py:416} INFO - Running <TaskInstance: pronostico_tiempo_dag1.insertar_datos manual__2023-10-14T21:42:09.462441+00:00 [running]> on host f314a0c7455b
[2023-10-14T21:47:36.399+0000] {taskinstance.py:1662} INFO - Exporting env vars: AIRFLOW_CTX_DAG_OWNER='Gustavo Lavalle' AIRFLOW_CTX_DAG_ID='pronostico_tiempo_dag1' AIRFLOW_CTX_TASK_ID='insertar_datos' AIRFLOW_CTX_EXECUTION_DATE='2023-10-14T21:42:09.462441+00:00' AIRFLOW_CTX_TRY_NUMBER='2' AIRFLOW_CTX_DAG_RUN_ID='manual__2023-10-14T21:42:09.462441+00:00'
[2023-10-14T21:47:36.415+0000] {taskinstance.py:1937} ERROR - Task failed with exception
Traceback (most recent call last):
  File "/home/airflow/.local/lib/python3.8/site-packages/airflow/operators/python.py", line 192, in execute
    return_value = self.execute_callable()
  File "/home/airflow/.local/lib/python3.8/site-packages/airflow/operators/python.py", line 209, in execute_callable
    return self.python_callable(*self.op_args, **self.op_kwargs)
  File "/opt/airflow/dags/tiempo1.py", line 76, in insertar_datos
    temperatura = pronostico['main']['temp']
TypeError: 'NoneType' object is not subscriptable
[2023-10-14T21:47:36.426+0000] {taskinstance.py:1400} INFO - Marking task as FAILED. dag_id=pronostico_tiempo_dag1, task_id=insertar_datos, execution_date=20231014T214209, start_date=20231014T214736, end_date=20231014T214736
[2023-10-14T21:47:36.444+0000] {standard_task_runner.py:104} ERROR - Failed to execute job 37 for task insertar_datos ('NoneType' object is not subscriptable; 1185)
[2023-10-14T21:47:36.455+0000] {local_task_job_runner.py:228} INFO - Task exited with return code 1
[2023-10-14T21:47:36.473+0000] {taskinstance.py:2778} INFO - 0 downstream tasks scheduled from follow-on schedule check
