[2023-10-13T01:14:42.443+0000] {processor.py:157} INFO - Started process (PID=29) to work on /opt/airflow/dags/tiempo.py
[2023-10-13T01:14:42.444+0000] {processor.py:829} INFO - Processing file /opt/airflow/dags/tiempo.py for tasks to queue
[2023-10-13T01:14:42.446+0000] {logging_mixin.py:151} INFO - [2023-10-13T01:14:42.446+0000] {dagbag.py:536} INFO - Filling up the DagBag from /opt/airflow/dags/tiempo.py
[2023-10-13T01:14:42.462+0000] {logging_mixin.py:151} INFO - [2023-10-13T01:14:42.460+0000] {dagbag.py:346} ERROR - Failed to import: /opt/airflow/dags/tiempo.py
Traceback (most recent call last):
  File "/home/airflow/.local/lib/python3.8/site-packages/airflow/models/dagbag.py", line 342, in parse
    loader.exec_module(new_module)
  File "<frozen importlib._bootstrap_external>", line 839, in exec_module
  File "<frozen importlib._bootstrap_external>", line 976, in get_code
  File "<frozen importlib._bootstrap_external>", line 906, in source_to_code
  File "<frozen importlib._bootstrap>", line 219, in _call_with_frames_removed
  File "/opt/airflow/dags/tiempo.py", line 27
    descarga_pronostico_task = PythonOperator(
    ^
IndentationError: expected an indented block
[2023-10-13T01:14:42.463+0000] {processor.py:841} WARNING - No viable dags retrieved from /opt/airflow/dags/tiempo.py
[2023-10-13T01:14:42.562+0000] {processor.py:179} INFO - Processing /opt/airflow/dags/tiempo.py took 0.145 seconds
[2023-10-13T01:15:12.785+0000] {processor.py:157} INFO - Started process (PID=84) to work on /opt/airflow/dags/tiempo.py
[2023-10-13T01:15:12.818+0000] {processor.py:829} INFO - Processing file /opt/airflow/dags/tiempo.py for tasks to queue
[2023-10-13T01:15:12.821+0000] {logging_mixin.py:151} INFO - [2023-10-13T01:15:12.820+0000] {dagbag.py:536} INFO - Filling up the DagBag from /opt/airflow/dags/tiempo.py
[2023-10-13T01:15:12.824+0000] {logging_mixin.py:151} INFO - [2023-10-13T01:15:12.823+0000] {dagbag.py:346} ERROR - Failed to import: /opt/airflow/dags/tiempo.py
Traceback (most recent call last):
  File "/home/airflow/.local/lib/python3.8/site-packages/airflow/models/dagbag.py", line 342, in parse
    loader.exec_module(new_module)
  File "<frozen importlib._bootstrap_external>", line 839, in exec_module
  File "<frozen importlib._bootstrap_external>", line 976, in get_code
  File "<frozen importlib._bootstrap_external>", line 906, in source_to_code
  File "<frozen importlib._bootstrap>", line 219, in _call_with_frames_removed
  File "/opt/airflow/dags/tiempo.py", line 27
    descarga_pronostico_task = PythonOperator(
    ^
IndentationError: expected an indented block
[2023-10-13T01:15:12.824+0000] {processor.py:841} WARNING - No viable dags retrieved from /opt/airflow/dags/tiempo.py
[2023-10-13T01:15:12.884+0000] {processor.py:179} INFO - Processing /opt/airflow/dags/tiempo.py took 0.105 seconds
[2023-10-13T01:15:43.332+0000] {processor.py:157} INFO - Started process (PID=138) to work on /opt/airflow/dags/tiempo.py
[2023-10-13T01:15:43.356+0000] {processor.py:829} INFO - Processing file /opt/airflow/dags/tiempo.py for tasks to queue
[2023-10-13T01:15:43.359+0000] {logging_mixin.py:151} INFO - [2023-10-13T01:15:43.358+0000] {dagbag.py:536} INFO - Filling up the DagBag from /opt/airflow/dags/tiempo.py
[2023-10-13T01:15:43.363+0000] {logging_mixin.py:151} INFO - [2023-10-13T01:15:43.362+0000] {dagbag.py:346} ERROR - Failed to import: /opt/airflow/dags/tiempo.py
Traceback (most recent call last):
  File "/home/airflow/.local/lib/python3.8/site-packages/airflow/models/dagbag.py", line 342, in parse
    loader.exec_module(new_module)
  File "<frozen importlib._bootstrap_external>", line 839, in exec_module
  File "<frozen importlib._bootstrap_external>", line 976, in get_code
  File "<frozen importlib._bootstrap_external>", line 906, in source_to_code
  File "<frozen importlib._bootstrap>", line 219, in _call_with_frames_removed
  File "/opt/airflow/dags/tiempo.py", line 27
    descarga_pronostico_task = PythonOperator(
    ^
IndentationError: expected an indented block
[2023-10-13T01:15:43.364+0000] {processor.py:841} WARNING - No viable dags retrieved from /opt/airflow/dags/tiempo.py
[2023-10-13T01:15:43.407+0000] {processor.py:179} INFO - Processing /opt/airflow/dags/tiempo.py took 0.079 seconds
[2023-10-13T01:16:13.581+0000] {processor.py:157} INFO - Started process (PID=192) to work on /opt/airflow/dags/tiempo.py
[2023-10-13T01:16:13.582+0000] {processor.py:829} INFO - Processing file /opt/airflow/dags/tiempo.py for tasks to queue
[2023-10-13T01:16:13.593+0000] {logging_mixin.py:151} INFO - [2023-10-13T01:16:13.592+0000] {dagbag.py:536} INFO - Filling up the DagBag from /opt/airflow/dags/tiempo.py
[2023-10-13T01:16:13.599+0000] {logging_mixin.py:151} INFO - [2023-10-13T01:16:13.596+0000] {dagbag.py:346} ERROR - Failed to import: /opt/airflow/dags/tiempo.py
Traceback (most recent call last):
  File "/home/airflow/.local/lib/python3.8/site-packages/airflow/models/dagbag.py", line 342, in parse
    loader.exec_module(new_module)
  File "<frozen importlib._bootstrap_external>", line 839, in exec_module
  File "<frozen importlib._bootstrap_external>", line 976, in get_code
  File "<frozen importlib._bootstrap_external>", line 906, in source_to_code
  File "<frozen importlib._bootstrap>", line 219, in _call_with_frames_removed
  File "/opt/airflow/dags/tiempo.py", line 27
    descarga_pronostico_task = PythonOperator(
    ^
IndentationError: expected an indented block
[2023-10-13T01:16:13.601+0000] {processor.py:841} WARNING - No viable dags retrieved from /opt/airflow/dags/tiempo.py
[2023-10-13T01:16:13.685+0000] {processor.py:179} INFO - Processing /opt/airflow/dags/tiempo.py took 0.109 seconds
[2023-10-13T01:16:43.928+0000] {processor.py:157} INFO - Started process (PID=247) to work on /opt/airflow/dags/tiempo.py
[2023-10-13T01:16:43.969+0000] {processor.py:829} INFO - Processing file /opt/airflow/dags/tiempo.py for tasks to queue
[2023-10-13T01:16:43.972+0000] {logging_mixin.py:151} INFO - [2023-10-13T01:16:43.972+0000] {dagbag.py:536} INFO - Filling up the DagBag from /opt/airflow/dags/tiempo.py
[2023-10-13T01:16:43.976+0000] {logging_mixin.py:151} INFO - [2023-10-13T01:16:43.975+0000] {dagbag.py:346} ERROR - Failed to import: /opt/airflow/dags/tiempo.py
Traceback (most recent call last):
  File "/home/airflow/.local/lib/python3.8/site-packages/airflow/models/dagbag.py", line 342, in parse
    loader.exec_module(new_module)
  File "<frozen importlib._bootstrap_external>", line 839, in exec_module
  File "<frozen importlib._bootstrap_external>", line 976, in get_code
  File "<frozen importlib._bootstrap_external>", line 906, in source_to_code
  File "<frozen importlib._bootstrap>", line 219, in _call_with_frames_removed
  File "/opt/airflow/dags/tiempo.py", line 27
    descarga_pronostico_task = PythonOperator(
    ^
IndentationError: expected an indented block
[2023-10-13T01:16:43.976+0000] {processor.py:841} WARNING - No viable dags retrieved from /opt/airflow/dags/tiempo.py
[2023-10-13T01:16:44.018+0000] {processor.py:179} INFO - Processing /opt/airflow/dags/tiempo.py took 0.097 seconds
[2023-10-13T01:17:14.377+0000] {processor.py:157} INFO - Started process (PID=301) to work on /opt/airflow/dags/tiempo.py
[2023-10-13T01:17:14.379+0000] {processor.py:829} INFO - Processing file /opt/airflow/dags/tiempo.py for tasks to queue
[2023-10-13T01:17:14.394+0000] {logging_mixin.py:151} INFO - [2023-10-13T01:17:14.394+0000] {dagbag.py:536} INFO - Filling up the DagBag from /opt/airflow/dags/tiempo.py
[2023-10-13T01:17:14.410+0000] {logging_mixin.py:151} INFO - [2023-10-13T01:17:14.409+0000] {dagbag.py:346} ERROR - Failed to import: /opt/airflow/dags/tiempo.py
Traceback (most recent call last):
  File "/home/airflow/.local/lib/python3.8/site-packages/airflow/models/dagbag.py", line 342, in parse
    loader.exec_module(new_module)
  File "<frozen importlib._bootstrap_external>", line 839, in exec_module
  File "<frozen importlib._bootstrap_external>", line 976, in get_code
  File "<frozen importlib._bootstrap_external>", line 906, in source_to_code
  File "<frozen importlib._bootstrap>", line 219, in _call_with_frames_removed
  File "/opt/airflow/dags/tiempo.py", line 27
    descarga_pronostico_task = PythonOperator(
    ^
IndentationError: expected an indented block
[2023-10-13T01:17:14.411+0000] {processor.py:841} WARNING - No viable dags retrieved from /opt/airflow/dags/tiempo.py
[2023-10-13T01:17:14.474+0000] {processor.py:179} INFO - Processing /opt/airflow/dags/tiempo.py took 0.107 seconds
[2023-10-13T01:17:44.862+0000] {processor.py:157} INFO - Started process (PID=357) to work on /opt/airflow/dags/tiempo.py
[2023-10-13T01:17:44.878+0000] {processor.py:829} INFO - Processing file /opt/airflow/dags/tiempo.py for tasks to queue
[2023-10-13T01:17:44.880+0000] {logging_mixin.py:151} INFO - [2023-10-13T01:17:44.880+0000] {dagbag.py:536} INFO - Filling up the DagBag from /opt/airflow/dags/tiempo.py
[2023-10-13T01:17:44.885+0000] {logging_mixin.py:151} INFO - [2023-10-13T01:17:44.883+0000] {dagbag.py:346} ERROR - Failed to import: /opt/airflow/dags/tiempo.py
Traceback (most recent call last):
  File "/home/airflow/.local/lib/python3.8/site-packages/airflow/models/dagbag.py", line 342, in parse
    loader.exec_module(new_module)
  File "<frozen importlib._bootstrap_external>", line 839, in exec_module
  File "<frozen importlib._bootstrap_external>", line 976, in get_code
  File "<frozen importlib._bootstrap_external>", line 906, in source_to_code
  File "<frozen importlib._bootstrap>", line 219, in _call_with_frames_removed
  File "/opt/airflow/dags/tiempo.py", line 27
    descarga_pronostico_task = PythonOperator(
    ^
IndentationError: expected an indented block
[2023-10-13T01:17:44.886+0000] {processor.py:841} WARNING - No viable dags retrieved from /opt/airflow/dags/tiempo.py
[2023-10-13T01:17:44.952+0000] {processor.py:179} INFO - Processing /opt/airflow/dags/tiempo.py took 0.094 seconds
[2023-10-13T01:18:15.377+0000] {processor.py:157} INFO - Started process (PID=412) to work on /opt/airflow/dags/tiempo.py
[2023-10-13T01:18:15.378+0000] {processor.py:829} INFO - Processing file /opt/airflow/dags/tiempo.py for tasks to queue
[2023-10-13T01:18:15.380+0000] {logging_mixin.py:151} INFO - [2023-10-13T01:18:15.380+0000] {dagbag.py:536} INFO - Filling up the DagBag from /opt/airflow/dags/tiempo.py
[2023-10-13T01:18:15.388+0000] {logging_mixin.py:151} INFO - [2023-10-13T01:18:15.387+0000] {dagbag.py:346} ERROR - Failed to import: /opt/airflow/dags/tiempo.py
Traceback (most recent call last):
  File "/home/airflow/.local/lib/python3.8/site-packages/airflow/models/dagbag.py", line 342, in parse
    loader.exec_module(new_module)
  File "<frozen importlib._bootstrap_external>", line 839, in exec_module
  File "<frozen importlib._bootstrap_external>", line 976, in get_code
  File "<frozen importlib._bootstrap_external>", line 906, in source_to_code
  File "<frozen importlib._bootstrap>", line 219, in _call_with_frames_removed
  File "/opt/airflow/dags/tiempo.py", line 27
    descarga_pronostico_task = PythonOperator(
    ^
IndentationError: expected an indented block
[2023-10-13T01:18:15.389+0000] {processor.py:841} WARNING - No viable dags retrieved from /opt/airflow/dags/tiempo.py
[2023-10-13T01:18:15.442+0000] {processor.py:179} INFO - Processing /opt/airflow/dags/tiempo.py took 0.069 seconds
[2023-10-13T01:18:45.998+0000] {processor.py:157} INFO - Started process (PID=467) to work on /opt/airflow/dags/tiempo.py
[2023-10-13T01:18:46.022+0000] {processor.py:829} INFO - Processing file /opt/airflow/dags/tiempo.py for tasks to queue
[2023-10-13T01:18:46.025+0000] {logging_mixin.py:151} INFO - [2023-10-13T01:18:46.024+0000] {dagbag.py:536} INFO - Filling up the DagBag from /opt/airflow/dags/tiempo.py
[2023-10-13T01:18:46.029+0000] {logging_mixin.py:151} INFO - [2023-10-13T01:18:46.028+0000] {dagbag.py:346} ERROR - Failed to import: /opt/airflow/dags/tiempo.py
Traceback (most recent call last):
  File "/home/airflow/.local/lib/python3.8/site-packages/airflow/models/dagbag.py", line 342, in parse
    loader.exec_module(new_module)
  File "<frozen importlib._bootstrap_external>", line 839, in exec_module
  File "<frozen importlib._bootstrap_external>", line 976, in get_code
  File "<frozen importlib._bootstrap_external>", line 906, in source_to_code
  File "<frozen importlib._bootstrap>", line 219, in _call_with_frames_removed
  File "/opt/airflow/dags/tiempo.py", line 27
    descarga_pronostico_task = PythonOperator(
    ^
IndentationError: expected an indented block
[2023-10-13T01:18:46.030+0000] {processor.py:841} WARNING - No viable dags retrieved from /opt/airflow/dags/tiempo.py
[2023-10-13T01:18:46.075+0000] {processor.py:179} INFO - Processing /opt/airflow/dags/tiempo.py took 0.084 seconds
[2023-10-13T01:19:16.281+0000] {processor.py:157} INFO - Started process (PID=522) to work on /opt/airflow/dags/tiempo.py
[2023-10-13T01:19:16.282+0000] {processor.py:829} INFO - Processing file /opt/airflow/dags/tiempo.py for tasks to queue
[2023-10-13T01:19:16.286+0000] {logging_mixin.py:151} INFO - [2023-10-13T01:19:16.286+0000] {dagbag.py:536} INFO - Filling up the DagBag from /opt/airflow/dags/tiempo.py
[2023-10-13T01:19:16.291+0000] {logging_mixin.py:151} INFO - [2023-10-13T01:19:16.289+0000] {dagbag.py:346} ERROR - Failed to import: /opt/airflow/dags/tiempo.py
Traceback (most recent call last):
  File "/home/airflow/.local/lib/python3.8/site-packages/airflow/models/dagbag.py", line 342, in parse
    loader.exec_module(new_module)
  File "<frozen importlib._bootstrap_external>", line 839, in exec_module
  File "<frozen importlib._bootstrap_external>", line 976, in get_code
  File "<frozen importlib._bootstrap_external>", line 906, in source_to_code
  File "<frozen importlib._bootstrap>", line 219, in _call_with_frames_removed
  File "/opt/airflow/dags/tiempo.py", line 27
    descarga_pronostico_task = PythonOperator(
    ^
IndentationError: expected an indented block
[2023-10-13T01:19:16.292+0000] {processor.py:841} WARNING - No viable dags retrieved from /opt/airflow/dags/tiempo.py
[2023-10-13T01:19:16.387+0000] {processor.py:179} INFO - Processing /opt/airflow/dags/tiempo.py took 0.112 seconds
[2023-10-13T01:19:46.747+0000] {processor.py:157} INFO - Started process (PID=577) to work on /opt/airflow/dags/tiempo.py
[2023-10-13T01:19:46.762+0000] {processor.py:829} INFO - Processing file /opt/airflow/dags/tiempo.py for tasks to queue
[2023-10-13T01:19:46.765+0000] {logging_mixin.py:151} INFO - [2023-10-13T01:19:46.765+0000] {dagbag.py:536} INFO - Filling up the DagBag from /opt/airflow/dags/tiempo.py
[2023-10-13T01:19:46.768+0000] {logging_mixin.py:151} INFO - [2023-10-13T01:19:46.767+0000] {dagbag.py:346} ERROR - Failed to import: /opt/airflow/dags/tiempo.py
Traceback (most recent call last):
  File "/home/airflow/.local/lib/python3.8/site-packages/airflow/models/dagbag.py", line 342, in parse
    loader.exec_module(new_module)
  File "<frozen importlib._bootstrap_external>", line 839, in exec_module
  File "<frozen importlib._bootstrap_external>", line 976, in get_code
  File "<frozen importlib._bootstrap_external>", line 906, in source_to_code
  File "<frozen importlib._bootstrap>", line 219, in _call_with_frames_removed
  File "/opt/airflow/dags/tiempo.py", line 27
    descarga_pronostico_task = PythonOperator(
    ^
IndentationError: expected an indented block
[2023-10-13T01:19:46.768+0000] {processor.py:841} WARNING - No viable dags retrieved from /opt/airflow/dags/tiempo.py
[2023-10-13T01:19:46.810+0000] {processor.py:179} INFO - Processing /opt/airflow/dags/tiempo.py took 0.069 seconds
[2023-10-13T01:20:08.812+0000] {processor.py:157} INFO - Started process (PID=632) to work on /opt/airflow/dags/tiempo.py
[2023-10-13T01:20:08.813+0000] {processor.py:829} INFO - Processing file /opt/airflow/dags/tiempo.py for tasks to queue
[2023-10-13T01:20:08.815+0000] {logging_mixin.py:151} INFO - [2023-10-13T01:20:08.814+0000] {dagbag.py:536} INFO - Filling up the DagBag from /opt/airflow/dags/tiempo.py
[2023-10-13T01:20:08.821+0000] {logging_mixin.py:151} INFO - [2023-10-13T01:20:08.820+0000] {dagbag.py:346} ERROR - Failed to import: /opt/airflow/dags/tiempo.py
Traceback (most recent call last):
  File "/home/airflow/.local/lib/python3.8/site-packages/airflow/models/dagbag.py", line 342, in parse
    loader.exec_module(new_module)
  File "<frozen importlib._bootstrap_external>", line 843, in exec_module
  File "<frozen importlib._bootstrap>", line 219, in _call_with_frames_removed
  File "/opt/airflow/dags/tiempo.py", line 24, in <module>
    python_callable=descargar_pronostico_del_tiempo,
NameError: name 'descargar_pronostico_del_tiempo' is not defined
[2023-10-13T01:20:08.821+0000] {processor.py:841} WARNING - No viable dags retrieved from /opt/airflow/dags/tiempo.py
[2023-10-13T01:20:08.865+0000] {processor.py:179} INFO - Processing /opt/airflow/dags/tiempo.py took 0.057 seconds
[2023-10-13T01:20:39.527+0000] {processor.py:157} INFO - Started process (PID=687) to work on /opt/airflow/dags/tiempo.py
[2023-10-13T01:20:39.578+0000] {processor.py:829} INFO - Processing file /opt/airflow/dags/tiempo.py for tasks to queue
[2023-10-13T01:20:39.582+0000] {logging_mixin.py:151} INFO - [2023-10-13T01:20:39.582+0000] {dagbag.py:536} INFO - Filling up the DagBag from /opt/airflow/dags/tiempo.py
[2023-10-13T01:20:39.590+0000] {logging_mixin.py:151} INFO - [2023-10-13T01:20:39.588+0000] {dagbag.py:346} ERROR - Failed to import: /opt/airflow/dags/tiempo.py
Traceback (most recent call last):
  File "/home/airflow/.local/lib/python3.8/site-packages/airflow/models/dagbag.py", line 342, in parse
    loader.exec_module(new_module)
  File "<frozen importlib._bootstrap_external>", line 843, in exec_module
  File "<frozen importlib._bootstrap>", line 219, in _call_with_frames_removed
  File "/opt/airflow/dags/tiempo.py", line 24, in <module>
    python_callable=descargar_pronostico_del_tiempo,
NameError: name 'descargar_pronostico_del_tiempo' is not defined
[2023-10-13T01:20:39.591+0000] {processor.py:841} WARNING - No viable dags retrieved from /opt/airflow/dags/tiempo.py
[2023-10-13T01:20:39.638+0000] {processor.py:179} INFO - Processing /opt/airflow/dags/tiempo.py took 0.115 seconds
[2023-10-13T01:21:09.759+0000] {processor.py:157} INFO - Started process (PID=743) to work on /opt/airflow/dags/tiempo.py
[2023-10-13T01:21:09.760+0000] {processor.py:829} INFO - Processing file /opt/airflow/dags/tiempo.py for tasks to queue
[2023-10-13T01:21:09.764+0000] {logging_mixin.py:151} INFO - [2023-10-13T01:21:09.763+0000] {dagbag.py:536} INFO - Filling up the DagBag from /opt/airflow/dags/tiempo.py
[2023-10-13T01:21:09.769+0000] {logging_mixin.py:151} INFO - [2023-10-13T01:21:09.768+0000] {dagbag.py:346} ERROR - Failed to import: /opt/airflow/dags/tiempo.py
Traceback (most recent call last):
  File "/home/airflow/.local/lib/python3.8/site-packages/airflow/models/dagbag.py", line 342, in parse
    loader.exec_module(new_module)
  File "<frozen importlib._bootstrap_external>", line 843, in exec_module
  File "<frozen importlib._bootstrap>", line 219, in _call_with_frames_removed
  File "/opt/airflow/dags/tiempo.py", line 24, in <module>
    python_callable=descargar_pronostico_del_tiempo,
NameError: name 'descargar_pronostico_del_tiempo' is not defined
[2023-10-13T01:21:09.769+0000] {processor.py:841} WARNING - No viable dags retrieved from /opt/airflow/dags/tiempo.py
[2023-10-13T01:21:09.822+0000] {processor.py:179} INFO - Processing /opt/airflow/dags/tiempo.py took 0.067 seconds
[2023-10-13T01:21:40.183+0000] {processor.py:157} INFO - Started process (PID=798) to work on /opt/airflow/dags/tiempo.py
[2023-10-13T01:21:40.205+0000] {processor.py:829} INFO - Processing file /opt/airflow/dags/tiempo.py for tasks to queue
[2023-10-13T01:21:40.207+0000] {logging_mixin.py:151} INFO - [2023-10-13T01:21:40.207+0000] {dagbag.py:536} INFO - Filling up the DagBag from /opt/airflow/dags/tiempo.py
[2023-10-13T01:21:40.223+0000] {logging_mixin.py:151} INFO - [2023-10-13T01:21:40.221+0000] {dagbag.py:346} ERROR - Failed to import: /opt/airflow/dags/tiempo.py
Traceback (most recent call last):
  File "/home/airflow/.local/lib/python3.8/site-packages/airflow/models/dagbag.py", line 342, in parse
    loader.exec_module(new_module)
  File "<frozen importlib._bootstrap_external>", line 843, in exec_module
  File "<frozen importlib._bootstrap>", line 219, in _call_with_frames_removed
  File "/opt/airflow/dags/tiempo.py", line 24, in <module>
    python_callable=descargar_pronostico_del_tiempo,
NameError: name 'descargar_pronostico_del_tiempo' is not defined
[2023-10-13T01:21:40.223+0000] {processor.py:841} WARNING - No viable dags retrieved from /opt/airflow/dags/tiempo.py
[2023-10-13T01:21:40.267+0000] {processor.py:179} INFO - Processing /opt/airflow/dags/tiempo.py took 0.089 seconds
[2023-10-13T01:21:41.206+0000] {processor.py:157} INFO - Started process (PID=799) to work on /opt/airflow/dags/tiempo.py
[2023-10-13T01:21:41.207+0000] {processor.py:829} INFO - Processing file /opt/airflow/dags/tiempo.py for tasks to queue
[2023-10-13T01:21:41.215+0000] {logging_mixin.py:151} INFO - [2023-10-13T01:21:41.214+0000] {dagbag.py:536} INFO - Filling up the DagBag from /opt/airflow/dags/tiempo.py
[2023-10-13T01:21:41.221+0000] {logging_mixin.py:151} INFO - [2023-10-13T01:21:41.219+0000] {dagbag.py:346} ERROR - Failed to import: /opt/airflow/dags/tiempo.py
Traceback (most recent call last):
  File "/home/airflow/.local/lib/python3.8/site-packages/airflow/models/dagbag.py", line 342, in parse
    loader.exec_module(new_module)
  File "<frozen importlib._bootstrap_external>", line 839, in exec_module
  File "<frozen importlib._bootstrap_external>", line 976, in get_code
  File "<frozen importlib._bootstrap_external>", line 906, in source_to_code
  File "<frozen importlib._bootstrap>", line 219, in _call_with_frames_removed
  File "/opt/airflow/dags/tiempo.py", line 27
    descarga_pronostico_task = PythonOperator(
    ^
IndentationError: expected an indented block
[2023-10-13T01:21:41.222+0000] {processor.py:841} WARNING - No viable dags retrieved from /opt/airflow/dags/tiempo.py
[2023-10-13T01:21:41.267+0000] {processor.py:179} INFO - Processing /opt/airflow/dags/tiempo.py took 0.081 seconds
[2023-10-13T01:24:37.559+0000] {processor.py:157} INFO - Started process (PID=30) to work on /opt/airflow/dags/tiempo.py
[2023-10-13T01:24:37.597+0000] {processor.py:829} INFO - Processing file /opt/airflow/dags/tiempo.py for tasks to queue
[2023-10-13T01:24:37.605+0000] {logging_mixin.py:151} INFO - [2023-10-13T01:24:37.604+0000] {dagbag.py:536} INFO - Filling up the DagBag from /opt/airflow/dags/tiempo.py
[2023-10-13T01:24:37.625+0000] {logging_mixin.py:151} INFO - [2023-10-13T01:24:37.609+0000] {dagbag.py:346} ERROR - Failed to import: /opt/airflow/dags/tiempo.py
Traceback (most recent call last):
  File "/home/airflow/.local/lib/python3.8/site-packages/airflow/models/dagbag.py", line 342, in parse
    loader.exec_module(new_module)
  File "<frozen importlib._bootstrap_external>", line 839, in exec_module
  File "<frozen importlib._bootstrap_external>", line 976, in get_code
  File "<frozen importlib._bootstrap_external>", line 906, in source_to_code
  File "<frozen importlib._bootstrap>", line 219, in _call_with_frames_removed
  File "/opt/airflow/dags/tiempo.py", line 27
    descarga_pronostico_task = PythonOperator(
    ^
IndentationError: expected an indented block
[2023-10-13T01:24:37.625+0000] {processor.py:841} WARNING - No viable dags retrieved from /opt/airflow/dags/tiempo.py
[2023-10-13T01:24:37.750+0000] {processor.py:179} INFO - Processing /opt/airflow/dags/tiempo.py took 0.198 seconds
[2023-10-13T01:25:08.017+0000] {processor.py:157} INFO - Started process (PID=85) to work on /opt/airflow/dags/tiempo.py
[2023-10-13T01:25:08.034+0000] {processor.py:829} INFO - Processing file /opt/airflow/dags/tiempo.py for tasks to queue
[2023-10-13T01:25:08.037+0000] {logging_mixin.py:151} INFO - [2023-10-13T01:25:08.037+0000] {dagbag.py:536} INFO - Filling up the DagBag from /opt/airflow/dags/tiempo.py
[2023-10-13T01:25:08.040+0000] {logging_mixin.py:151} INFO - [2023-10-13T01:25:08.039+0000] {dagbag.py:346} ERROR - Failed to import: /opt/airflow/dags/tiempo.py
Traceback (most recent call last):
  File "/home/airflow/.local/lib/python3.8/site-packages/airflow/models/dagbag.py", line 342, in parse
    loader.exec_module(new_module)
  File "<frozen importlib._bootstrap_external>", line 839, in exec_module
  File "<frozen importlib._bootstrap_external>", line 976, in get_code
  File "<frozen importlib._bootstrap_external>", line 906, in source_to_code
  File "<frozen importlib._bootstrap>", line 219, in _call_with_frames_removed
  File "/opt/airflow/dags/tiempo.py", line 27
    descarga_pronostico_task = PythonOperator(
    ^
IndentationError: expected an indented block
[2023-10-13T01:25:08.041+0000] {processor.py:841} WARNING - No viable dags retrieved from /opt/airflow/dags/tiempo.py
[2023-10-13T01:25:08.083+0000] {processor.py:179} INFO - Processing /opt/airflow/dags/tiempo.py took 0.071 seconds
[2023-10-13T01:25:38.470+0000] {processor.py:157} INFO - Started process (PID=140) to work on /opt/airflow/dags/tiempo.py
[2023-10-13T01:25:38.472+0000] {processor.py:829} INFO - Processing file /opt/airflow/dags/tiempo.py for tasks to queue
[2023-10-13T01:25:38.475+0000] {logging_mixin.py:151} INFO - [2023-10-13T01:25:38.475+0000] {dagbag.py:536} INFO - Filling up the DagBag from /opt/airflow/dags/tiempo.py
[2023-10-13T01:25:38.506+0000] {logging_mixin.py:151} INFO - [2023-10-13T01:25:38.505+0000] {dagbag.py:346} ERROR - Failed to import: /opt/airflow/dags/tiempo.py
Traceback (most recent call last):
  File "/home/airflow/.local/lib/python3.8/site-packages/airflow/models/dagbag.py", line 342, in parse
    loader.exec_module(new_module)
  File "<frozen importlib._bootstrap_external>", line 839, in exec_module
  File "<frozen importlib._bootstrap_external>", line 976, in get_code
  File "<frozen importlib._bootstrap_external>", line 906, in source_to_code
  File "<frozen importlib._bootstrap>", line 219, in _call_with_frames_removed
  File "/opt/airflow/dags/tiempo.py", line 27
    descarga_pronostico_task = PythonOperator(
    ^
IndentationError: expected an indented block
[2023-10-13T01:25:38.507+0000] {processor.py:841} WARNING - No viable dags retrieved from /opt/airflow/dags/tiempo.py
[2023-10-13T01:25:38.551+0000] {processor.py:179} INFO - Processing /opt/airflow/dags/tiempo.py took 0.090 seconds
[2023-10-13T01:26:09.063+0000] {processor.py:157} INFO - Started process (PID=194) to work on /opt/airflow/dags/tiempo.py
[2023-10-13T01:26:09.141+0000] {processor.py:829} INFO - Processing file /opt/airflow/dags/tiempo.py for tasks to queue
[2023-10-13T01:26:09.144+0000] {logging_mixin.py:151} INFO - [2023-10-13T01:26:09.144+0000] {dagbag.py:536} INFO - Filling up the DagBag from /opt/airflow/dags/tiempo.py
[2023-10-13T01:26:09.148+0000] {logging_mixin.py:151} INFO - [2023-10-13T01:26:09.147+0000] {dagbag.py:346} ERROR - Failed to import: /opt/airflow/dags/tiempo.py
Traceback (most recent call last):
  File "/home/airflow/.local/lib/python3.8/site-packages/airflow/models/dagbag.py", line 342, in parse
    loader.exec_module(new_module)
  File "<frozen importlib._bootstrap_external>", line 839, in exec_module
  File "<frozen importlib._bootstrap_external>", line 976, in get_code
  File "<frozen importlib._bootstrap_external>", line 906, in source_to_code
  File "<frozen importlib._bootstrap>", line 219, in _call_with_frames_removed
  File "/opt/airflow/dags/tiempo.py", line 27
    descarga_pronostico_task = PythonOperator(
    ^
IndentationError: expected an indented block
[2023-10-13T01:26:09.149+0000] {processor.py:841} WARNING - No viable dags retrieved from /opt/airflow/dags/tiempo.py
[2023-10-13T01:26:09.196+0000] {processor.py:179} INFO - Processing /opt/airflow/dags/tiempo.py took 0.136 seconds
[2023-10-13T01:26:39.701+0000] {processor.py:157} INFO - Started process (PID=249) to work on /opt/airflow/dags/tiempo.py
[2023-10-13T01:26:39.702+0000] {processor.py:829} INFO - Processing file /opt/airflow/dags/tiempo.py for tasks to queue
[2023-10-13T01:26:39.706+0000] {logging_mixin.py:151} INFO - [2023-10-13T01:26:39.706+0000] {dagbag.py:536} INFO - Filling up the DagBag from /opt/airflow/dags/tiempo.py
[2023-10-13T01:26:39.711+0000] {logging_mixin.py:151} INFO - [2023-10-13T01:26:39.709+0000] {dagbag.py:346} ERROR - Failed to import: /opt/airflow/dags/tiempo.py
Traceback (most recent call last):
  File "/home/airflow/.local/lib/python3.8/site-packages/airflow/models/dagbag.py", line 342, in parse
    loader.exec_module(new_module)
  File "<frozen importlib._bootstrap_external>", line 839, in exec_module
  File "<frozen importlib._bootstrap_external>", line 976, in get_code
  File "<frozen importlib._bootstrap_external>", line 906, in source_to_code
  File "<frozen importlib._bootstrap>", line 219, in _call_with_frames_removed
  File "/opt/airflow/dags/tiempo.py", line 27
    descarga_pronostico_task = PythonOperator(
    ^
IndentationError: expected an indented block
[2023-10-13T01:26:39.712+0000] {processor.py:841} WARNING - No viable dags retrieved from /opt/airflow/dags/tiempo.py
[2023-10-13T01:26:39.796+0000] {processor.py:179} INFO - Processing /opt/airflow/dags/tiempo.py took 0.103 seconds
[2023-10-13T01:27:09.916+0000] {processor.py:157} INFO - Started process (PID=304) to work on /opt/airflow/dags/tiempo.py
[2023-10-13T01:27:09.921+0000] {processor.py:829} INFO - Processing file /opt/airflow/dags/tiempo.py for tasks to queue
[2023-10-13T01:27:09.923+0000] {logging_mixin.py:151} INFO - [2023-10-13T01:27:09.923+0000] {dagbag.py:536} INFO - Filling up the DagBag from /opt/airflow/dags/tiempo.py
[2023-10-13T01:27:09.927+0000] {logging_mixin.py:151} INFO - [2023-10-13T01:27:09.926+0000] {dagbag.py:346} ERROR - Failed to import: /opt/airflow/dags/tiempo.py
Traceback (most recent call last):
  File "/home/airflow/.local/lib/python3.8/site-packages/airflow/models/dagbag.py", line 342, in parse
    loader.exec_module(new_module)
  File "<frozen importlib._bootstrap_external>", line 839, in exec_module
  File "<frozen importlib._bootstrap_external>", line 976, in get_code
  File "<frozen importlib._bootstrap_external>", line 906, in source_to_code
  File "<frozen importlib._bootstrap>", line 219, in _call_with_frames_removed
  File "/opt/airflow/dags/tiempo.py", line 27
    descarga_pronostico_task = PythonOperator(
    ^
IndentationError: expected an indented block
[2023-10-13T01:27:09.928+0000] {processor.py:841} WARNING - No viable dags retrieved from /opt/airflow/dags/tiempo.py
[2023-10-13T01:27:10.053+0000] {processor.py:179} INFO - Processing /opt/airflow/dags/tiempo.py took 0.141 seconds
[2023-10-13T01:27:40.418+0000] {processor.py:157} INFO - Started process (PID=359) to work on /opt/airflow/dags/tiempo.py
[2023-10-13T01:27:40.419+0000] {processor.py:829} INFO - Processing file /opt/airflow/dags/tiempo.py for tasks to queue
[2023-10-13T01:27:40.421+0000] {logging_mixin.py:151} INFO - [2023-10-13T01:27:40.421+0000] {dagbag.py:536} INFO - Filling up the DagBag from /opt/airflow/dags/tiempo.py
[2023-10-13T01:27:40.425+0000] {logging_mixin.py:151} INFO - [2023-10-13T01:27:40.424+0000] {dagbag.py:346} ERROR - Failed to import: /opt/airflow/dags/tiempo.py
Traceback (most recent call last):
  File "/home/airflow/.local/lib/python3.8/site-packages/airflow/models/dagbag.py", line 342, in parse
    loader.exec_module(new_module)
  File "<frozen importlib._bootstrap_external>", line 839, in exec_module
  File "<frozen importlib._bootstrap_external>", line 976, in get_code
  File "<frozen importlib._bootstrap_external>", line 906, in source_to_code
  File "<frozen importlib._bootstrap>", line 219, in _call_with_frames_removed
  File "/opt/airflow/dags/tiempo.py", line 27
    descarga_pronostico_task = PythonOperator(
    ^
IndentationError: expected an indented block
[2023-10-13T01:27:40.425+0000] {processor.py:841} WARNING - No viable dags retrieved from /opt/airflow/dags/tiempo.py
[2023-10-13T01:27:40.510+0000] {processor.py:179} INFO - Processing /opt/airflow/dags/tiempo.py took 0.096 seconds
