[2023-10-14T20:40:06.608+0000] {taskinstance.py:1159} INFO - Dependencies all met for dep_context=non-requeueable deps ti=<TaskInstance: pronostico_tiempo_dag.obtener_pronostico manual__2023-10-14T20:40:02.935971+00:00 [queued]>
[2023-10-14T20:40:06.637+0000] {taskinstance.py:1159} INFO - Dependencies all met for dep_context=requeueable deps ti=<TaskInstance: pronostico_tiempo_dag.obtener_pronostico manual__2023-10-14T20:40:02.935971+00:00 [queued]>
[2023-10-14T20:40:06.638+0000] {taskinstance.py:1361} INFO - Starting attempt 1 of 2
[2023-10-14T20:40:06.704+0000] {taskinstance.py:1382} INFO - Executing <Task(PythonOperator): obtener_pronostico> on 2023-10-14 20:40:02.935971+00:00
[2023-10-14T20:40:06.712+0000] {standard_task_runner.py:57} INFO - Started process 200 to run task
[2023-10-14T20:40:06.722+0000] {standard_task_runner.py:84} INFO - Running: ['***', 'tasks', 'run', 'pronostico_tiempo_dag', 'obtener_pronostico', 'manual__2023-10-14T20:40:02.935971+00:00', '--job-id', '16', '--raw', '--subdir', 'DAGS_FOLDER/tiempo.py', '--cfg-path', '/tmp/tmp4vrtecn_']
[2023-10-14T20:40:06.742+0000] {standard_task_runner.py:85} INFO - Job 16: Subtask obtener_pronostico
[2023-10-14T20:40:07.031+0000] {task_command.py:416} INFO - Running <TaskInstance: pronostico_tiempo_dag.obtener_pronostico manual__2023-10-14T20:40:02.935971+00:00 [running]> on host f314a0c7455b
[2023-10-14T20:40:07.418+0000] {taskinstance.py:1662} INFO - Exporting env vars: AIRFLOW_CTX_DAG_OWNER='Gustavo Lavalle' AIRFLOW_CTX_DAG_ID='pronostico_tiempo_dag' AIRFLOW_CTX_TASK_ID='obtener_pronostico' AIRFLOW_CTX_EXECUTION_DATE='2023-10-14T20:40:02.935971+00:00' AIRFLOW_CTX_TRY_NUMBER='1' AIRFLOW_CTX_DAG_RUN_ID='manual__2023-10-14T20:40:02.935971+00:00'
[2023-10-14T20:40:07.429+0000] {taskinstance.py:1937} ERROR - Task failed with exception
Traceback (most recent call last):
  File "/home/airflow/.local/lib/python3.8/site-packages/airflow/operators/python.py", line 192, in execute
    return_value = self.execute_callable()
  File "/home/airflow/.local/lib/python3.8/site-packages/airflow/operators/python.py", line 209, in execute_callable
    return self.python_callable(*self.op_args, **self.op_kwargs)
TypeError: obtener_pronostico() takes 1 positional argument but 3 were given
[2023-10-14T20:40:07.474+0000] {taskinstance.py:1400} INFO - Marking task as UP_FOR_RETRY. dag_id=pronostico_tiempo_dag, task_id=obtener_pronostico, execution_date=20231014T204002, start_date=20231014T204006, end_date=20231014T204007
[2023-10-14T20:40:07.581+0000] {standard_task_runner.py:104} ERROR - Failed to execute job 16 for task obtener_pronostico (obtener_pronostico() takes 1 positional argument but 3 were given; 200)
[2023-10-14T20:40:07.638+0000] {local_task_job_runner.py:228} INFO - Task exited with return code 1
[2023-10-14T20:40:07.755+0000] {taskinstance.py:2778} INFO - 0 downstream tasks scheduled from follow-on schedule check
