[2023-10-14T23:00:39.798+0000] {taskinstance.py:1159} INFO - Dependencies all met for dep_context=non-requeueable deps ti=<TaskInstance: pronostico_tiempo_dag1.insertar_datos_raw manual__2023-10-14T23:00:19.312363+00:00 [queued]>
[2023-10-14T23:00:39.833+0000] {taskinstance.py:1159} INFO - Dependencies all met for dep_context=requeueable deps ti=<TaskInstance: pronostico_tiempo_dag1.insertar_datos_raw manual__2023-10-14T23:00:19.312363+00:00 [queued]>
[2023-10-14T23:00:39.833+0000] {taskinstance.py:1361} INFO - Starting attempt 1 of 2
[2023-10-14T23:00:39.894+0000] {taskinstance.py:1382} INFO - Executing <Task(PythonOperator): insertar_datos_raw> on 2023-10-14 23:00:19.312363+00:00
[2023-10-14T23:00:39.908+0000] {standard_task_runner.py:57} INFO - Started process 2313 to run task
[2023-10-14T23:00:39.915+0000] {standard_task_runner.py:84} INFO - Running: ['***', 'tasks', 'run', 'pronostico_tiempo_dag1', 'insertar_datos_raw', 'manual__2023-10-14T23:00:19.312363+00:00', '--job-id', '73', '--raw', '--subdir', 'DAGS_FOLDER/tiempo1.py', '--cfg-path', '/tmp/tmp848ymrni']
[2023-10-14T23:00:39.920+0000] {standard_task_runner.py:85} INFO - Job 73: Subtask insertar_datos_raw
[2023-10-14T23:00:40.052+0000] {task_command.py:416} INFO - Running <TaskInstance: pronostico_tiempo_dag1.insertar_datos_raw manual__2023-10-14T23:00:19.312363+00:00 [running]> on host f314a0c7455b
[2023-10-14T23:00:40.415+0000] {taskinstance.py:1662} INFO - Exporting env vars: AIRFLOW_CTX_DAG_OWNER='Gustavo Lavalle' AIRFLOW_CTX_DAG_ID='pronostico_tiempo_dag1' AIRFLOW_CTX_TASK_ID='insertar_datos_raw' AIRFLOW_CTX_EXECUTION_DATE='2023-10-14T23:00:19.312363+00:00' AIRFLOW_CTX_TRY_NUMBER='1' AIRFLOW_CTX_DAG_RUN_ID='manual__2023-10-14T23:00:19.312363+00:00'
[2023-10-14T23:00:40.465+0000] {taskinstance.py:1937} ERROR - Task failed with exception
Traceback (most recent call last):
  File "/home/airflow/.local/lib/python3.8/site-packages/airflow/operators/python.py", line 192, in execute
    return_value = self.execute_callable()
  File "/home/airflow/.local/lib/python3.8/site-packages/airflow/operators/python.py", line 209, in execute_callable
    return self.python_callable(*self.op_args, **self.op_kwargs)
  File "/opt/airflow/dags/tiempo1.py", line 124, in insertar_datos_raw
    pronostico_json = json.dumps(pronostico[1])
NameError: name 'json' is not defined
[2023-10-14T23:00:40.498+0000] {taskinstance.py:1400} INFO - Marking task as UP_FOR_RETRY. dag_id=pronostico_tiempo_dag1, task_id=insertar_datos_raw, execution_date=20231014T230019, start_date=20231014T230039, end_date=20231014T230040
[2023-10-14T23:00:40.537+0000] {standard_task_runner.py:104} ERROR - Failed to execute job 73 for task insertar_datos_raw (name 'json' is not defined; 2313)
[2023-10-14T23:00:40.559+0000] {local_task_job_runner.py:228} INFO - Task exited with return code 1
[2023-10-14T23:00:40.604+0000] {taskinstance.py:2778} INFO - 0 downstream tasks scheduled from follow-on schedule check
