[2023-10-14T22:33:46.440+0000] {taskinstance.py:1159} INFO - Dependencies all met for dep_context=non-requeueable deps ti=<TaskInstance: pronostico_tiempo_dag1.insertar_datos manual__2023-10-14T22:30:25.371632+00:00 [queued]>
[2023-10-14T22:33:46.500+0000] {taskinstance.py:1159} INFO - Dependencies all met for dep_context=requeueable deps ti=<TaskInstance: pronostico_tiempo_dag1.insertar_datos manual__2023-10-14T22:30:25.371632+00:00 [queued]>
[2023-10-14T22:33:46.500+0000] {taskinstance.py:1361} INFO - Starting attempt 2 of 3
[2023-10-14T22:33:46.924+0000] {taskinstance.py:1382} INFO - Executing <Task(PythonOperator): insertar_datos> on 2023-10-14 22:30:25.371632+00:00
[2023-10-14T22:33:46.932+0000] {standard_task_runner.py:57} INFO - Started process 1884 to run task
[2023-10-14T22:33:46.938+0000] {standard_task_runner.py:84} INFO - Running: ['***', 'tasks', 'run', 'pronostico_tiempo_dag1', 'insertar_datos', 'manual__2023-10-14T22:30:25.371632+00:00', '--job-id', '56', '--raw', '--subdir', 'DAGS_FOLDER/tiempo1.py', '--cfg-path', '/tmp/tmp2nzr5afn']
[2023-10-14T22:33:46.951+0000] {standard_task_runner.py:85} INFO - Job 56: Subtask insertar_datos
[2023-10-14T22:33:47.448+0000] {task_command.py:416} INFO - Running <TaskInstance: pronostico_tiempo_dag1.insertar_datos manual__2023-10-14T22:30:25.371632+00:00 [running]> on host f314a0c7455b
[2023-10-14T22:33:47.775+0000] {taskinstance.py:1662} INFO - Exporting env vars: AIRFLOW_CTX_DAG_OWNER='Gustavo Lavalle' AIRFLOW_CTX_DAG_ID='pronostico_tiempo_dag1' AIRFLOW_CTX_TASK_ID='insertar_datos' AIRFLOW_CTX_EXECUTION_DATE='2023-10-14T22:30:25.371632+00:00' AIRFLOW_CTX_TRY_NUMBER='2' AIRFLOW_CTX_DAG_RUN_ID='manual__2023-10-14T22:30:25.371632+00:00'
[2023-10-14T22:33:47.828+0000] {taskinstance.py:1937} ERROR - Task failed with exception
Traceback (most recent call last):
  File "/home/airflow/.local/lib/python3.8/site-packages/airflow/operators/python.py", line 192, in execute
    return_value = self.execute_callable()
  File "/home/airflow/.local/lib/python3.8/site-packages/airflow/operators/python.py", line 209, in execute_callable
    return self.python_callable(*self.op_args, **self.op_kwargs)
  File "/opt/airflow/dags/tiempo1.py", line 99, in insertar_datos_postgres
    cursor.execute("INSERT INTO RAW (ciudad, temperatura_actual, temperatura_maxima, temperatura_minima, presion, humedad) VALUES (%s, %s, %s, %s, %s, %s)", (ciudad, pronostico[1]['temperatura_actual'], pronostico[1]['temperatura_maxima'], pronostico[1]['temperatura_minima'], pronostico[1]['presion'], pronostico[1]['humedad']))
psycopg2.errors.UndefinedColumn: column "temperatura_actual" of relation "raw" does not exist
LINE 1: INSERT INTO RAW (ciudad, temperatura_actual, temperatura_max...
                                 ^

[2023-10-14T22:33:47.861+0000] {taskinstance.py:1400} INFO - Marking task as UP_FOR_RETRY. dag_id=pronostico_tiempo_dag1, task_id=insertar_datos, execution_date=20231014T223025, start_date=20231014T223346, end_date=20231014T223347
[2023-10-14T22:33:47.910+0000] {standard_task_runner.py:104} ERROR - Failed to execute job 56 for task insertar_datos (column "temperatura_actual" of relation "raw" does not exist
LINE 1: INSERT INTO RAW (ciudad, temperatura_actual, temperatura_max...
                                 ^
; 1884)
[2023-10-14T22:33:47.969+0000] {local_task_job_runner.py:228} INFO - Task exited with return code 1
[2023-10-14T22:33:48.038+0000] {taskinstance.py:2778} INFO - 0 downstream tasks scheduled from follow-on schedule check
