[2023-10-14T21:38:01.371+0000] {taskinstance.py:1159} INFO - Dependencies all met for dep_context=non-requeueable deps ti=<TaskInstance: pronostico_tiempo_dag1.insertar_datos manual__2023-10-14T21:37:45.388491+00:00 [queued]>
[2023-10-14T21:38:01.404+0000] {taskinstance.py:1159} INFO - Dependencies all met for dep_context=requeueable deps ti=<TaskInstance: pronostico_tiempo_dag1.insertar_datos manual__2023-10-14T21:37:45.388491+00:00 [queued]>
[2023-10-14T21:38:01.405+0000] {taskinstance.py:1361} INFO - Starting attempt 1 of 2
[2023-10-14T21:38:01.479+0000] {taskinstance.py:1382} INFO - Executing <Task(PythonOperator): insertar_datos> on 2023-10-14 21:37:45.388491+00:00
[2023-10-14T21:38:01.498+0000] {standard_task_runner.py:57} INFO - Started process 1034 to run task
[2023-10-14T21:38:01.510+0000] {standard_task_runner.py:84} INFO - Running: ['***', 'tasks', 'run', 'pronostico_tiempo_dag1', 'insertar_datos', 'manual__2023-10-14T21:37:45.388491+00:00', '--job-id', '28', '--raw', '--subdir', 'DAGS_FOLDER/tiempo1.py', '--cfg-path', '/tmp/tmp4yrqb7q7']
[2023-10-14T21:38:01.517+0000] {standard_task_runner.py:85} INFO - Job 28: Subtask insertar_datos
[2023-10-14T21:38:01.672+0000] {task_command.py:416} INFO - Running <TaskInstance: pronostico_tiempo_dag1.insertar_datos manual__2023-10-14T21:37:45.388491+00:00 [running]> on host f314a0c7455b
[2023-10-14T21:38:01.869+0000] {taskinstance.py:1662} INFO - Exporting env vars: AIRFLOW_CTX_DAG_OWNER='Gustavo Lavalle' AIRFLOW_CTX_DAG_ID='pronostico_tiempo_dag1' AIRFLOW_CTX_TASK_ID='insertar_datos' AIRFLOW_CTX_EXECUTION_DATE='2023-10-14T21:37:45.388491+00:00' AIRFLOW_CTX_TRY_NUMBER='1' AIRFLOW_CTX_DAG_RUN_ID='manual__2023-10-14T21:37:45.388491+00:00'
[2023-10-14T21:38:01.904+0000] {taskinstance.py:1937} ERROR - Task failed with exception
Traceback (most recent call last):
  File "/home/airflow/.local/lib/python3.8/site-packages/airflow/operators/python.py", line 192, in execute
    return_value = self.execute_callable()
  File "/home/airflow/.local/lib/python3.8/site-packages/airflow/operators/python.py", line 209, in execute_callable
    return self.python_callable(*self.op_args, **self.op_kwargs)
  File "/opt/airflow/dags/tiempo1.py", line 75, in insertar_datos
    temperatura = pronostico['main']['temp']
TypeError: 'NoneType' object is not subscriptable
[2023-10-14T21:38:01.920+0000] {taskinstance.py:1400} INFO - Marking task as UP_FOR_RETRY. dag_id=pronostico_tiempo_dag1, task_id=insertar_datos, execution_date=20231014T213745, start_date=20231014T213801, end_date=20231014T213801
[2023-10-14T21:38:01.957+0000] {standard_task_runner.py:104} ERROR - Failed to execute job 28 for task insertar_datos ('NoneType' object is not subscriptable; 1034)
[2023-10-14T21:38:01.974+0000] {local_task_job_runner.py:228} INFO - Task exited with return code 1
[2023-10-14T21:38:02.012+0000] {taskinstance.py:2778} INFO - 0 downstream tasks scheduled from follow-on schedule check
