[2023-10-14T23:12:16.844+0000] {taskinstance.py:1159} INFO - Dependencies all met for dep_context=non-requeueable deps ti=<TaskInstance: pronostico_tiempo_dag1.insertar_datos_staging manual__2023-10-14T23:11:43.935554+00:00 [queued]>
[2023-10-14T23:12:16.874+0000] {taskinstance.py:1159} INFO - Dependencies all met for dep_context=requeueable deps ti=<TaskInstance: pronostico_tiempo_dag1.insertar_datos_staging manual__2023-10-14T23:11:43.935554+00:00 [queued]>
[2023-10-14T23:12:16.875+0000] {taskinstance.py:1361} INFO - Starting attempt 1 of 2
[2023-10-14T23:12:16.915+0000] {taskinstance.py:1382} INFO - Executing <Task(PythonOperator): insertar_datos_staging> on 2023-10-14 23:11:43.935554+00:00
[2023-10-14T23:12:16.931+0000] {standard_task_runner.py:57} INFO - Started process 2502 to run task
[2023-10-14T23:12:16.936+0000] {standard_task_runner.py:84} INFO - Running: ['***', 'tasks', 'run', 'pronostico_tiempo_dag1', 'insertar_datos_staging', 'manual__2023-10-14T23:11:43.935554+00:00', '--job-id', '83', '--raw', '--subdir', 'DAGS_FOLDER/tiempo1.py', '--cfg-path', '/tmp/tmp20_9z7su']
[2023-10-14T23:12:16.941+0000] {standard_task_runner.py:85} INFO - Job 83: Subtask insertar_datos_staging
[2023-10-14T23:12:17.100+0000] {task_command.py:416} INFO - Running <TaskInstance: pronostico_tiempo_dag1.insertar_datos_staging manual__2023-10-14T23:11:43.935554+00:00 [running]> on host f314a0c7455b
[2023-10-14T23:12:17.333+0000] {taskinstance.py:1662} INFO - Exporting env vars: AIRFLOW_CTX_DAG_OWNER='Gustavo Lavalle' AIRFLOW_CTX_DAG_ID='pronostico_tiempo_dag1' AIRFLOW_CTX_TASK_ID='insertar_datos_staging' AIRFLOW_CTX_EXECUTION_DATE='2023-10-14T23:11:43.935554+00:00' AIRFLOW_CTX_TRY_NUMBER='1' AIRFLOW_CTX_DAG_RUN_ID='manual__2023-10-14T23:11:43.935554+00:00'
[2023-10-14T23:12:17.366+0000] {taskinstance.py:1937} ERROR - Task failed with exception
Traceback (most recent call last):
  File "/home/airflow/.local/lib/python3.8/site-packages/airflow/operators/python.py", line 192, in execute
    return_value = self.execute_callable()
  File "/home/airflow/.local/lib/python3.8/site-packages/airflow/operators/python.py", line 209, in execute_callable
    return self.python_callable(*self.op_args, **self.op_kwargs)
  File "/opt/airflow/dags/tiempo1.py", line 158, in insertar_datos_staging
    fecha_hora_sql = fecha_hora.strftime("%Y-%m-%d %H:%M:%S")
AttributeError: 'str' object has no attribute 'strftime'
[2023-10-14T23:12:17.383+0000] {taskinstance.py:1400} INFO - Marking task as UP_FOR_RETRY. dag_id=pronostico_tiempo_dag1, task_id=insertar_datos_staging, execution_date=20231014T231143, start_date=20231014T231216, end_date=20231014T231217
[2023-10-14T23:12:17.414+0000] {standard_task_runner.py:104} ERROR - Failed to execute job 83 for task insertar_datos_staging ('str' object has no attribute 'strftime'; 2502)
[2023-10-14T23:12:17.437+0000] {local_task_job_runner.py:228} INFO - Task exited with return code 1
[2023-10-14T23:12:17.484+0000] {taskinstance.py:2778} INFO - 0 downstream tasks scheduled from follow-on schedule check
