[2023-10-14T20:34:45.921+0000] {taskinstance.py:1159} INFO - Dependencies all met for dep_context=non-requeueable deps ti=<TaskInstance: pronostico_tiempo_dag.obtener_pronostico manual__2023-10-14T20:34:26.670478+00:00 [queued]>
[2023-10-14T20:34:45.936+0000] {taskinstance.py:1159} INFO - Dependencies all met for dep_context=requeueable deps ti=<TaskInstance: pronostico_tiempo_dag.obtener_pronostico manual__2023-10-14T20:34:26.670478+00:00 [queued]>
[2023-10-14T20:34:45.937+0000] {taskinstance.py:1361} INFO - Starting attempt 1 of 2
[2023-10-14T20:34:45.994+0000] {taskinstance.py:1382} INFO - Executing <Task(PythonOperator): obtener_pronostico> on 2023-10-14 20:34:26.670478+00:00
[2023-10-14T20:34:46.006+0000] {standard_task_runner.py:57} INFO - Started process 120 to run task
[2023-10-14T20:34:46.015+0000] {standard_task_runner.py:84} INFO - Running: ['***', 'tasks', 'run', 'pronostico_tiempo_dag', 'obtener_pronostico', 'manual__2023-10-14T20:34:26.670478+00:00', '--job-id', '13', '--raw', '--subdir', 'DAGS_FOLDER/tiempo.py', '--cfg-path', '/tmp/tmp3xx5tg21']
[2023-10-14T20:34:46.023+0000] {standard_task_runner.py:85} INFO - Job 13: Subtask obtener_pronostico
[2023-10-14T20:34:46.144+0000] {task_command.py:416} INFO - Running <TaskInstance: pronostico_tiempo_dag.obtener_pronostico manual__2023-10-14T20:34:26.670478+00:00 [running]> on host f314a0c7455b
[2023-10-14T20:34:46.361+0000] {taskinstance.py:1662} INFO - Exporting env vars: AIRFLOW_CTX_DAG_OWNER='Gustavo Lavalle' AIRFLOW_CTX_DAG_ID='pronostico_tiempo_dag' AIRFLOW_CTX_TASK_ID='obtener_pronostico' AIRFLOW_CTX_EXECUTION_DATE='2023-10-14T20:34:26.670478+00:00' AIRFLOW_CTX_TRY_NUMBER='1' AIRFLOW_CTX_DAG_RUN_ID='manual__2023-10-14T20:34:26.670478+00:00'
[2023-10-14T20:34:46.375+0000] {taskinstance.py:1937} ERROR - Task failed with exception
Traceback (most recent call last):
  File "/home/airflow/.local/lib/python3.8/site-packages/airflow/operators/python.py", line 192, in execute
    return_value = self.execute_callable()
  File "/home/airflow/.local/lib/python3.8/site-packages/airflow/operators/python.py", line 209, in execute_callable
    return self.python_callable(*self.op_args, **self.op_kwargs)
TypeError: obtener_pronostico() takes 1 positional argument but 3 were given
[2023-10-14T20:34:46.408+0000] {taskinstance.py:1400} INFO - Marking task as UP_FOR_RETRY. dag_id=pronostico_tiempo_dag, task_id=obtener_pronostico, execution_date=20231014T203426, start_date=20231014T203445, end_date=20231014T203446
[2023-10-14T20:34:46.471+0000] {standard_task_runner.py:104} ERROR - Failed to execute job 13 for task obtener_pronostico (obtener_pronostico() takes 1 positional argument but 3 were given; 120)
[2023-10-14T20:34:46.515+0000] {local_task_job_runner.py:228} INFO - Task exited with return code 1
[2023-10-14T20:34:46.561+0000] {taskinstance.py:2778} INFO - 0 downstream tasks scheduled from follow-on schedule check
